<?xml version="1.0" ?>
<!-- =================================================================================== -->
<!-- |    This document was autogenerated by xacro from /home/flora/Workspace/catkin_hera/src/hera_description/robots/hera_full.urdf.xacro | -->
<!-- |    EDITING THIS FILE BY HAND IS NOT RECOMMENDED                                 | -->
<!-- =================================================================================== -->
<robot name="hera" xmlns:controller="http://playerstage.sourceforge.net/gazebo/xmlschema/#controller" xmlns:interface="http://playerstage.sourceforge.net/gazebo/xmlschema/#interface" xmlns:sensor="http://playerstage.sourceforge.net/gazebo/xmlschema/#sensor">
    <!-- <xacro:arg name="prefix" default="" /> -->
    <!-- ##################################################################### -->
    <!-- ######################### includes ################################## -->
    <!-- ##################################################################### -->
    <!-- colors -->
    <material name="black">
        <color rgba="0.0 0.0 0.0 1.0" />
    </material>
    <material name="dark_grey">
        <color rgba="0.25 0.25 0.25 1.0" />
    </material>
    <material name="grey">
        <color rgba="0.5 0.5 0.5 1.0" />
    </material>
    <material name="light_grey">
        <color rgba="0.75 0.75 0.75 1.0" />
    </material>
    <material name="white">
        <color rgba="1.0 1.0 1.0 1.0" />
    </material>
    <!-- Macros -->
    <!-- choose kinect or zed-->
    <gazebo reference="base">
        <material>Gazebo/Black</material>
        <plugin name="gazebo_ros_control">
            <robotNamespace>/</robotNamespace>
        </plugin>
    </gazebo>
    <gazebo reference="base_wheelFR">
        <material>Gazebo/White</material>
    </gazebo>
    <gazebo reference="base_wheelFL">
        <material>Gazebo/White</material>
    </gazebo>
    <gazebo reference="base_wheelBR">
        <material>Gazebo/White</material>
    </gazebo>
    <gazebo reference="base_wheelBL">
        <material>Gazebo/White</material>
    </gazebo>
    <gazebo reference="torso">
        <material>Gazebo/DarkGray</material>
    </gazebo>
    <gazebo reference="torso_sensor_plat">
        <material>Gazebo/DarkGray</material>
    </gazebo>
    <gazebo reference="head">
        <material>Gazebo/Gray</material>
    </gazebo>
    <gazebo>
        <plugin filename="libgazebo_ros_control.so" name="gazebo_ros_control">
            <robotNamespace>/</robotNamespace>
            <robotSimType>gazebo_ros_control/DefaultRobotHWSim</robotSimType>
        </plugin>
    </gazebo>
    <!-- ####################################################################### -->
    <!-- ######################## robot parts ################################## -->
    <!-- ####################################################################### -->
    <!-- footprint -->
    <link name="base_footprint" />
    <joint name="joint_base_footprint_to_base" type="fixed">
        <origin xyz="0 0 0.1" />
        <parent link="base_footprint" />
        <child link="base" />
    </joint>
    <!-- base -->
    <link name="base">
        <inertial>
            <mass value="99.0" />
            <inertia ixx="0.782925" ixy="0.0" ixz="0.0" iyy="2.102925" iyz="0.0" izz="2.8049999999999997" />
            <origin xyz="0 0 0" rpy="0 0 0" />
        </inertial>
        <collision name="collision">
            <origin rpy="0 0 0" xyz="0 0 0" />
            <geometry>
                <box size="0.5 0.3 0.07" />
            </geometry>
        </collision>
        <visual>
            <material name="black" />
            <geometry>
                <mesh filename="package://hera_description/meshes/base.stl" />
            </geometry>
        </visual>
    </link>
    <link name="base_wheelFR">
        <inertial>
            <mass value="2.5" />
            <inertia ixx="0.007270833333333334" ixy="0.0" ixz="0.0" iyy="0.007270833333333334" iyz="0.0" izz="0.0125" />
            <origin xyz="0 0 0" rpy="0 0 0" />
        </inertial>
        <collision name="collision">
            <origin rpy="1.5707963267948966 0 0" xyz="0 0 0" />
            <geometry>
                <cylinder length="0.07" radius="0.1" />
            </geometry>
        </collision>
        <visual>
            <origin rpy=" 0 0 -1.5707963267948966" xyz="0 -0.045 0" />
            <material name="white" />
            <geometry>
                <mesh filename="package://hera_description/meshes/wheelF.stl" />
            </geometry>
        </visual>
        <inertial>
            <mass value="0.001" />
            <inertia ixx="1.0000000000000002e-08" ixy="0.0" ixz="0.0" iyy="1.0000000000000002e-08" iyz="0.0" izz="1.0000000000000002e-08" />
        </inertial>
        <collision name="collision">
            <origin rpy="0 0 0" xyz="0 0 -0.1" />
            <geometry>
                <sphere radius="0.005" />
            </geometry>
        </collision>
        <!-- wheel suport -->
    </link>
    <!-- should be continuous. Change if you do not use wheel support -->
    <joint name="joint_base_to_base_wheelFR" type="fixed">
        <origin rpy="0 0 0" xyz="0.2 -0.205 0.0" />
        <parent link="base" />
        <child link="base_wheelFR" />
        <!-- enable when joint type is continuous -->
        <!-- <axis xyz="0 1 0"/> -->
        <!-- <limit effort="${wheel_effort}" velocity="${wheel_velocity}"/> -->
    </joint>
    <link name="base_wheelFL">
        <inertial>
            <mass value="2.5" />
            <inertia ixx="0.007270833333333334" ixy="0.0" ixz="0.0" iyy="0.007270833333333334" iyz="0.0" izz="0.0125" />
            <origin xyz="0 0 0" rpy="0 0 0" />
        </inertial>
        <collision name="collision">
            <origin rpy="1.5707963267948966 0 0" xyz="0 0 0" />
            <geometry>
                <cylinder length="0.07" radius="0.1" />
            </geometry>
        </collision>
        <visual>
            <origin rpy=" 0 0 1.5707963267948966" xyz="0 0.045 0" />
            <material name="white" />
            <geometry>
                <mesh filename="package://hera_description/meshes/wheelF.stl" />
            </geometry>
        </visual>
        <inertial>
            <mass value="0.001" />
            <inertia ixx="1.0000000000000002e-08" ixy="0.0" ixz="0.0" iyy="1.0000000000000002e-08" iyz="0.0" izz="1.0000000000000002e-08" />
        </inertial>
        <collision name="collision">
            <origin rpy="0 0 0" xyz="0 0 -0.1" />
            <geometry>
                <sphere radius="0.005" />
            </geometry>
        </collision>
        <!-- wheel suport -->
    </link>
    <!-- should be continuous. Change if you do not use wheel support -->
    <joint name="joint_base_to_base_wheelFL" type="fixed">
        <origin rpy="0 0 0" xyz="0.2 0.205 0.0" />
        <parent link="base" />
        <child link="base_wheelFL" />
        <!-- enable when joint type is continuous -->
        <!-- <axis xyz="0 1 0"/> -->
        <!-- <limit effort="${wheel_effort}" velocity="${wheel_velocity}"/> -->
    </joint>
    <link name="base_wheelBR">
        <inertial>
            <mass value="2.5" />
            <inertia ixx="0.007270833333333334" ixy="0.0" ixz="0.0" iyy="0.007270833333333334" iyz="0.0" izz="0.0125" />
            <origin xyz="0 0 0" rpy="0 0 0" />
        </inertial>
        <collision name="collision">
            <origin rpy="1.5707963267948966 0 0" xyz="0 0 0" />
            <geometry>
                <cylinder length="0.07" radius="0.1" />
            </geometry>
        </collision>
        <visual>
            <origin rpy="0 0 -1.5707963267948966" xyz="0 -0.045 0" />
            <material name="white" />
            <geometry>
                <mesh filename="package://hera_description/meshes/wheelB.stl" />
            </geometry>
        </visual>
        <inertial>
            <mass value="0.001" />
            <inertia ixx="1.0000000000000002e-08" ixy="0.0" ixz="0.0" iyy="1.0000000000000002e-08" iyz="0.0" izz="1.0000000000000002e-08" />
        </inertial>
        <collision name="collision">
            <origin rpy="0 0 0" xyz="0 0 -0.1" />
            <geometry>
                <sphere radius="0.005" />
            </geometry>
        </collision>
        <!-- wheel suport -->
    </link>
    <!-- should be continuous. Change if you do not use wheel support -->
    <joint name="joint_base_to_base_wheelBR" type="fixed">
        <origin rpy="0 0 0" xyz="-0.2 -0.205 0.0" />
        <parent link="base" />
        <child link="base_wheelBR" />
        <!-- enable when joint type is continuous -->
        <!-- <axis xyz="0 1 0"/> -->
        <!-- <limit effort="${wheel_effort}" velocity="${wheel_velocity}"/> -->
    </joint>
    <link name="base_wheelBL">
        <inertial>
            <mass value="2.5" />
            <inertia ixx="0.007270833333333334" ixy="0.0" ixz="0.0" iyy="0.007270833333333334" iyz="0.0" izz="0.0125" />
            <origin xyz="0 0 0" rpy="0 0 0" />
        </inertial>
        <collision name="collision">
            <origin rpy="1.5707963267948966 0 0" xyz="0 0 0" />
            <geometry>
                <cylinder length="0.07" radius="0.1" />
            </geometry>
        </collision>
        <visual>
            <origin rpy="0 0 1.5707963267948966" xyz="0 0.045 0" />
            <material name="white" />
            <geometry>
                <mesh filename="package://hera_description/meshes/wheelB.stl" />
            </geometry>
        </visual>
        <inertial>
            <mass value="0.001" />
            <inertia ixx="1.0000000000000002e-08" ixy="0.0" ixz="0.0" iyy="1.0000000000000002e-08" iyz="0.0" izz="1.0000000000000002e-08" />
        </inertial>
        <collision name="collision">
            <origin rpy="0 0 0" xyz="0 0 -0.1" />
            <geometry>
                <sphere radius="0.005" />
            </geometry>
        </collision>
        <!-- wheel suport -->
    </link>
    <!-- should be continuous. Change if you do not use wheel support -->
    <joint name="joint_base_to_base_wheelBL" type="fixed">
        <origin rpy="0 0 0" xyz="-0.2 0.205 0.0" />
        <parent link="base" />
        <child link="base_wheelBL" />
        <!-- enable when joint type is continuous -->
        <!-- <axis xyz="0 1 0"/> -->
        <!-- <limit effort="${wheel_effort}" velocity="${wheel_velocity}"/> -->
    </joint>
    <!-- torso -->
    <link name="torso">
        <inertial>
            <mass value="1.0" />
            <inertia ixx="0.03270833333333334" ixy="0.0" ixz="0.0" iyy="0.03270833333333334" iyz="0.0" izz="0.015" />
            <origin xyz="0 0 0" rpy="0 0 0" />
        </inertial>
        <collision name="collision">
            <origin rpy="0 0 0" xyz="-0.1 0 -0.225" />
            <geometry>
                <box size="0.3 0.3 0.55" />
            </geometry>
        </collision>
        <inertial>
            <mass value="0.5" />
            <inertia ixx="0.0075" ixy="0.0" ixz="0.0" iyy="0.005416666666666667" iyz="0.0" izz="0.005416666666666667" />
        </inertial>
        <collision name="collision">
            <origin rpy="0 0 0" xyz="0.15 0 -0.35" />
            <geometry>
                <box size="0.2 0.3 0.3" />
            </geometry>
        </collision>
        <inertial>
            <mass value="0.1" />
            <inertia ixx="0.0007708333333333333" ixy="0.0" ixz="0.0" iyy="0.0010416666666666664" iyz="0.0" izz="0.001770833333333333" />
        </inertial>
        <collision name="collision">
            <origin rpy="0 0 0" xyz="-0.06 0 0.475" />
            <geometry>
                <box size="0.35 0.3 0.05" />
            </geometry>
        </collision>
        <inertial>
            <mass value="0.2" />
            <inertia ixx="0.016726666666666667" ixy="0.0" ixz="0.0" iyy="0.016948333333333333" iyz="0.0" izz="0.00034166666666666666" />
        </inertial>
        <collision name="collision">
            <origin rpy="0 0 0" xyz="-0.06 -0.18 0" />
            <geometry>
                <box size="0.13 0.06 1.0" />
            </geometry>
        </collision>
        <inertial>
            <mass value="0.2" />
            <inertia ixx="0.016726666666666667" ixy="0.0" ixz="0.0" iyy="0.016948333333333333" iyz="0.0" izz="0.00034166666666666666" />
        </inertial>
        <collision name="collision">
            <origin rpy="0 0 0" xyz="-0.06 0.18 0" />
            <geometry>
                <box size="0.13 0.06 1.0" />
            </geometry>
        </collision>
        <visual>
            <origin rpy="0 0 0" xyz="0 0 -0.5" />
            <material name="dark_grey" />
            <geometry>
                <mesh filename="package://hera_description/meshes/torso.stl" />
            </geometry>
        </visual>
        <collision>
            <origin rpy="0 0 0" xyz="0 0 -0.5" />
            <material name="dark_grey" />
            <geometry>
                <mesh filename="package://hera_description/meshes/torso.stl" />
            </geometry>
        </collision>
    </link>
    <!-- sensor plat -->
    <link name="torso_sensor_plat">
        <inertial>
            <mass value="0.01" />
            <inertia ixx="1.2083333333333332e-05" ixy="0.0" ixz="0.0" iyy="8.416666666666667e-06" iyz="0.0" izz="2.0333333333333334e-05" />
            <origin xyz="0 0 0" rpy="0 0 0" />
        </inertial>
        <collision name="collision">
            <origin rpy="0 0 0" xyz="0 0 0.05" />
            <geometry>
                <box size="0.1 0.12 0.01" />
            </geometry>
        </collision>
        <visual>
            <origin rpy="0 0 0" xyz="0.2 0 -0.2" />
            <material name="dark_grey" />
            <geometry>
                <mesh filename="package://hera_description/meshes/torso_sensor_plat.stl" />
            </geometry>
        </visual>
    </link>
    <joint name="joint_base_to_torso" type="fixed">
        <origin rpy="0 0 0" xyz="0 0 0.535" />
        <parent link="base" />
        <child link="torso" />
    </joint>
    <joint name="joint_torso_to_torso_sensor_plat" type="revolute">
        <origin rpy="0 0 0" xyz="0.09 0 0.46" />
        <parent link="torso" />
        <child link="torso_sensor_plat" />
        <axis xyz="0 -1 0" />
        <limit effort="30" lower="-1.5" upper="0.1" velocity="0.5" />
    </joint>
    <transmission name="tran_torso_sensor_plat">
        <type>transmission_interface/SimpleTransmission</type>
        <joint name="joint_torso_to_torso_sensor_plat">
            <hardwareInterface>hardware_interface/EffortJointInterface</hardwareInterface>
        </joint>
        <actuator name="motor_torso_sensor_plat">
            <hardwareInterface>hardware_interface/EffortJointInterface</hardwareInterface>
            <mechanicalReduction>1</mechanicalReduction>
        </actuator>
    </transmission>
    <!-- head -->
    <link name="head">
        <inertial>
            <mass value="0.01" />
            <inertia ixx="1.35625e-05" ixy="0.0" ixz="0.0" iyy="1.35625e-05" iyz="0.0" izz="2.1125000000000002e-05" />
            <origin xyz="0 0 0" rpy="0 0 0" />
        </inertial>
        <collision name="collision">
            <origin rpy="0 0 0" xyz="0 0 -0.165" />
            <geometry>
                <cylinder length="0.06" radius="0.065" />
            </geometry>
        </collision>
        <inertial>
            <mass value="0.02" />
            <inertia ixx="0.00018816666666666667" ixy="0.0" ixz="0.0" iyy="0.00013816666666666667" iyz="0.0" izz="8.333333333333334e-05" />
        </inertial>
        <collision name="collision">
            <origin rpy="0 0 0" xyz="0 0 0" />
            <geometry>
                <box size="0.1 0.2 0.27" />
            </geometry>
        </collision>
        <inertial>
            <mass value="0.01" />
            <inertia ixx="2.5083333333333338e-05" ixy="0.0" ixz="0.0" iyy="2.5083333333333338e-05" iyz="0.0" izz="2.0000000000000003e-06" />
        </inertial>
        <collision name="collision">
            <origin rpy="0 1.45 0" xyz="0.04 -0.13 0.05" />
            <geometry>
                <cylinder length="0.17" radius="0.02" />
            </geometry>
        </collision>
        <inertial>
            <mass value="0.01" />
            <inertia ixx="2.5083333333333338e-05" ixy="0.0" ixz="0.0" iyy="2.5083333333333338e-05" iyz="0.0" izz="2.0000000000000003e-06" />
        </inertial>
        <collision name="collision">
            <origin rpy="0 1.45 0" xyz="0.04 0.13 0.05" />
            <geometry>
                <cylinder length="0.17" radius="0.02" />
            </geometry>
        </collision>
        <visual>
            <origin rpy="0 0 0" xyz="0 0 -0.195" />
            <material name="grey" />
            <geometry>
                <mesh filename="package://hera_description/meshes/head.stl" />
            </geometry>
        </visual>
    </link>
    <joint name="joint_torso_to_head" type="fixed">
        <origin rpy="0 0 0" xyz="-0.06 0 0.6950000000000001" />
        <child link="head" />
        <parent link="torso" />
        <axis xyz="0 0 1" />
        <limit effort="30" lower="-1.5707963267948966" upper="1.5707963267948966" velocity="0.5" />
    </joint>
    <transmission name="tran_head">
        <type>transmission_interface/SimpleTransmission</type>
        <joint name="joint_torso_to_head">
            <hardwareInterface>hardware_interface/EffortJointInterface</hardwareInterface>
        </joint>
        <actuator name="motor_head">
            <hardwareInterface>hardware_interface/EffortJointInterface</hardwareInterface>
            <mechanicalReduction>1</mechanicalReduction>
        </actuator>
    </transmission>
    <link name="base_scan_front" type="laser">
        <inertial>
            <mass value="0.01" />
            <inertia ixx="9.749999999999998e-06" ixy="0.0" ixz="0.0" iyy="9.749999999999998e-06" iyz="0.0" izz="5.999999999999999e-06" />
            <origin xyz="0 0 0" rpy="0 0 0" />
        </inertial>
        <collision name="collision">
            <origin rpy="0 0 0" xyz="0 0 0" />
            <geometry>
                <box size="0.06 0.06 0.09" />
            </geometry>
        </collision>
        <visual>
            <origin rpy="1.5707963267948966 0 0" xyz="0 0 0" />
            <geometry>
                <mesh filename="package://hera_description/meshes/hokuyo_utm.stl" />
            </geometry>
        </visual>
    </link>
    <joint name="base_scan_front_hokuyo_utm_joint" type="fixed">
        <origin rpy="0 0 0" xyz="0.3 0 0.01" />
        <parent link="base" />
        <child link="base_scan_front" />
    </joint>
    <link name="base_scan_back" type="laser">
        <inertial>
            <mass value="0.01" />
            <inertia ixx="6.166666666666667e-06" ixy="0.0" ixz="0.0" iyy="6.166666666666667e-06" iyz="0.0" izz="4.166666666666667e-06" />
            <origin xyz="0 0 0" rpy="0 0 0" />
        </inertial>
        <collision name="collision">
            <origin rpy="0 0 0" xyz="0 0 0" />
            <geometry>
                <box size="0.05 0.05 0.07" />
            </geometry>
        </collision>
        <visual>
            <origin rpy="0 0 0" xyz="0 0 0" />
            <geometry>
                <mesh filename="package://hera_description/meshes/hokuyo_urg.dae" />
            </geometry>
        </visual>
    </link>
    <joint name="joint_base_to_base_scan_back_hokuyo_urg" type="fixed">
        <origin rpy="0 0 3.141592653589793" xyz="-0.3 0 0.01" />
        <parent link="base" />
        <child link="base_scan_back" />
    </joint>
    <!-- xtion -->
    <link name="xtion_link">
        <inertial>
            <mass value="0.01" />
            <inertia ixx="3.1083333333333334e-05" ixy="0.0" ixz="0.0" iyy="5.416666666666667e-06" iyz="0.0" izz="2.833333333333333e-05" />
            <origin xyz="0 0 0" rpy="0 0 0" />
        </inertial>
        <collision name="collision">
            <origin rpy="0 0 0" xyz="0 0 0" />
            <geometry>
                <box size="0.04 0.18 0.07" />
            </geometry>
        </collision>
        <visual>
            <origin rpy="1.5707963267948966 0.0 1.5707963267948966" xyz="0.02 0.025 0" />
            <geometry>
                <mesh filename="package://hera_description/meshes/asus_xtion.stl" />
            </geometry>
        </visual>
    </link>
    <joint name="joint_torso_to_xtion_link" type="fixed">
        <origin rpy="0 0 0" xyz="0.215 0 -0.17" />
        <parent link="torso" />
        <child link="xtion_link" />
    </joint>
    <link name="xtion_link_depth" />
    <joint name="joint_xtion_link_to_xtion_link_depth" type="fixed">
        <origin rpy="0 0 0" xyz="0.0 0.049 0.016" />
        <parent link="xtion_link" />
        <child link="xtion_link_depth" />
    </joint>
    <link name="xtion_link_optical" />
    <joint name="joint_xtion_link_to_xtion_link_otptical" type="fixed">
        <origin rpy="-1.5707963267948966 0 -1.5707963267948966" xyz="0 0 0" />
        <parent link="xtion_link" />
        <child link="xtion_link_optical" />
    </joint>
    <!-- zed -->
    <!-- <xacro:if value="${camera == 'zed'}">    
    <xacro:zed_camera name="zed" model="zed2" parent="torso_sensor_plat">
      <origin xyz="0.015 0 0.085" rpy="0 0 0" />
    </xacro:zed_camera>
  </xacro:if> -->
    <link name="manip_support_link">
        <visual>
            <origin rpy="0 0 0" xyz="0 0 0" />
            <geometry>
                <mesh filename="package://hera_description/meshes/manip_meshes/manip_support.STL" />
            </geometry>
            <material name="grey">
                <color rgba="0.792156862745098 0.819607843137255 0.933333333333333 1" />
            </material>
        </visual>
        <collision>
            <origin rpy="0 0 0" xyz="0 0 0" />
            <geometry>
                <mesh filename="package://hera_description/meshes/manip_meshes/manip_support.STL" />
            </geometry>
        </collision>
        <inertial>
            <origin rpy="0 0 0" xyz="0.099437810671345 2.00188811166901E-07 0.0198713294048926" />
            <mass value="0.659217140679788" />
            <inertia ixx="0.000498685766551954" ixy="4.35797776215065E-09" ixz="-0.000221629766113691" iyy="0.00233391280566028" iyz="5.90356892037055E-09" izz="0.00260971250229957" />
        </inertial>
    </link>
    <!--manip_support_joint-->
    <joint name="manip_support_joint" type="fixed">
        <origin rpy="0 0 0" xyz="0.04525 0 0.0285" />
        <parent link="torso" />
        <child link="manip_support_link" />
        <axis xyz="0 0 0" />
        <limit effort="0" lower="0" upper="0" velocity="0" />
    </joint>
    <link name="backrest_link">
        <visual>
            <origin rpy="0 0 0" xyz="0 0 0" />
            <geometry>
                <mesh filename="package://hera_description/meshes/manip_meshes/backrest.STL" />
            </geometry>
            <material name="grey">
                <color rgba="0.898039215686275 0.917647058823529 0.929411764705882 1" />
            </material>
        </visual>
        <collision>
            <origin rpy="0 0 0" xyz="0 0 0" />
            <geometry>
                <mesh filename="package://hera_description/meshes/manip_meshes/backrest.STL" />
            </geometry>
        </collision>
        <inertial>
            <origin rpy="0 0 0" xyz="0.00515298283191654 -0.00667089588666656 0.110700863109422" />
            <mass value="0.0709912944888601" />
            <inertia ixx="0.00019606850493542" ixy="-8.60297419203407E-20" ixz="-4.60131708471049E-20" iyy="0.000183353038292849" iyz="-1.01509944145167E-19" izz="2.15450520465379E-05" />
        </inertial>
    </link>
    <!--backrest_joint-->
    <joint name="backrest_joint" type="fixed">
        <origin rpy="0 0 0" xyz="0.028 0.0066709 0.053" />
        <parent link="torso" />
        <child link="backrest_link" />
        <axis xyz="0 0 0" />
        <limit effort="0" velocity="0" />
    </joint>
    <link name="manip_base_link">
        <visual>
            <origin rpy="0 0 0" xyz="0 0 0" />
            <geometry>
                <mesh filename="package://hera_description/meshes/manip_meshes/manip_base.STL" />
            </geometry>
            <material name="dark_grey" />
        </visual>
        <collision>
            <origin rpy="0 0 0" xyz="0 0 0" />
            <geometry>
                <mesh filename="package://hera_description/meshes/manip_meshes/manip_base_col.STL" />
            </geometry>
        </collision>
        <inertial>
            <origin rpy="0 0 0" xyz="0.00030938336056912 -9.89895665437501E-13 0.0229511892881233" />
            <mass value="0.225814419604843" />
            <inertia ixx="5.65453718592828E-05" ixy="5.00162232371705E-16" ixz="-1.38639831470138E-06" iyy="0.000101241328443196" iyz="-3.18870100704921E-15" izz="8.47747908239031E-05" />
        </inertial>
    </link>
    <!--manip_base_joint-->
    <joint name="manip_base_joint" type="fixed">
        <origin rpy="0 0 0" xyz="0.27075 0 0.0295" />
        <parent link="manip_support_link" />
        <child link="manip_base_link" />
        <axis xyz="0 0 0" />
        <limit effort="0" lower="0" upper="0" velocity="0" />
    </joint>
    <link name="shoulder_pan_link">
        <visual>
            <origin rpy="0 0 0" xyz="0 0 0" />
            <geometry>
                <mesh filename="package://hera_description/meshes/manip_meshes/shoulder_pan.STL" />
            </geometry>
            <material name="dark_grey">
                <color rgba="0.996078431372549 0.996078431372549 1 1" />
            </material>
        </visual>
        <collision>
            <origin rpy="0 0 0" xyz="0 0 0" />
            <geometry>
                <mesh filename="package://hera_description/meshes/manip_meshes/shoulder_pan_col.STL" />
            </geometry>
        </collision>
        <inertial>
            <origin rpy="0 0 0" xyz="0.010403379929175 1.63335446591584E-08 0.0169657675518438" />
            <mass value="0.0289102664622999" />
            <inertia ixx="2.12284942933575E-05" ixy="2.48129475489142E-12" ixz="-1.76897405605609E-06" iyy="1.25993311294143E-05" iyz="3.2054762687646E-12" izz="2.59552674841784E-05" />
        </inertial>
    </link>
    <!--joint_1: shoulder_pan_joint-->
    <joint name="shoulder_pan_joint" type="revolute">
        <origin rpy="0 0 0" xyz="0.0155 0 0.04515" />
        <parent link="manip_base_link" />
        <child link="shoulder_pan_link" />
        <axis xyz="0 0 1" />
        <limit effort="0" lower="-1.57" upper="1.57" velocity="5" />
    </joint>
    <link name="shoulder_lift_link">
        <visual>
            <origin rpy="0 0 0" xyz="0 0 0" />
            <geometry>
                <mesh filename="package://hera_description/meshes/manip_meshes/shoulder_lift.STL" />
            </geometry>
            <material name="dark_grey">
                <color rgba="0.898039215686275 0.917647058823529 0.929411764705882 1" />
            </material>
        </visual>
        <collision>
            <origin rpy="0 0 0" xyz="0 0 0" />
            <geometry>
                <mesh filename="package://hera_description/meshes/manip_meshes/shoulder_lift_col.STL" />
            </geometry>
        </collision>
        <inertial>
            <origin rpy="0 0 0" xyz="0.0763705857165563 0.000254475982597022 0.00808212627192917" />
            <mass value="0.611796741662792" />
            <inertia ixx="0.000193142254231562" ixy="4.37085471306953E-07" ixz="-1.72353751616987E-05" iyy="0.000387146626280563" iyz="-1.13959846344025E-12" izz="0.000310532195206607" />
        </inertial>
    </link>
    <!--joint_2: shoulder_lift_joint-->
    <joint name="shoulder_lift_joint" type="revolute">
        <origin rpy="3.1416 -1.1781 -3.1416" xyz="0.048 0 0.02285" />
        <parent link="shoulder_pan_link" />
        <child link="shoulder_lift_link" />
        <axis xyz="0 1 0" />
        <limit effort="0" lower="-0.9" upper="3.55" velocity="5" />
    </joint>
    <link name="elbow_pan_link">
        <visual>
            <origin rpy="0 0 0" xyz="0 0 0" />
            <geometry>
                <mesh filename="package://hera_description/meshes/manip_meshes/elbow_pan.STL" />
            </geometry>
            <material name="dark_grey">
                <color rgba="0.996078431372549 0.996078431372549 1 1" />
            </material>
        </visual>
        <collision>
            <origin rpy="0 0 0" xyz="0 0 0" />
            <geometry>
                <mesh filename="package://hera_description/meshes/manip_meshes/elbow_pan_col.STL" />
            </geometry>
        </collision>
        <inertial>
            <origin rpy="0 0 0" xyz="0.0169657676446836 1.64819090528456E-08 -0.0104033800071373" />
            <mass value="0.0289102660424069" />
            <inertia ixx="2.5955267230398E-05" ixy="3.22328296007298E-12" ixz="1.76897404833607E-06" iyy="1.25993310604571E-05" iyz="-2.56726778703582E-12" izz="2.12284940766909E-05" />
        </inertial>
    </link>
    <!--joint_3: elbow_pan_joint-->
    <joint name="elbow_pan_joint" type="revolute">
        <origin rpy="0 0 0" xyz="0.1439 0 0" />
        <parent link="shoulder_lift_link" />
        <child link="elbow_pan_link" />
        <axis xyz="1 0 0" />
        <limit effort="0" lower="-1.57" upper="1.57" velocity="5" />
    </joint>
    <link name="elbow_lift_link">
        <visual>
            <origin rpy="0 0 0" xyz="0 0 0" />
            <geometry>
                <mesh filename="package://hera_description/meshes/manip_meshes/elbow_lift.STL" />
            </geometry>
            <material name="dark_grey">
                <color rgba="0.898039215686275 0.917647058823529 0.929411764705882 1" />
            </material>
        </visual>
        <collision>
            <origin rpy="0 0 0" xyz="0 0 0" />
            <geometry>
                <mesh filename="package://hera_description/meshes/manip_meshes/elbow_lift_col.STL" />
            </geometry>
        </collision>
        <inertial>
            <origin rpy="0 0 0" xyz="0.0763705857419602 -0.00025447598295664 0.00808212650131321" />
            <mass value="0.611796742118779" />
            <inertia ixx="0.000193142254252889" ixy="-4.37085476272942E-07" ixz="-1.72353755052685E-05" iyy="0.000387146626356831" iyz="-1.13953084591342E-12" izz="0.000310532195285594" />
        </inertial>
    </link>
    <!--joint_4: elbow_lift_joint-->
    <joint name="elbow_lift_joint" type="revolute">
        <origin rpy="0 -0.3927 0" xyz="0.02285 0 -0.048" />
        <parent link="elbow_pan_link" />
        <child link="elbow_lift_link" />
        <axis xyz="0 -1 0" />
        <limit effort="0" lower="-3.55" upper="0.9" velocity="5" />
    </joint>
    <link name="wrist_pan_link">
        <visual>
            <origin rpy="0 0 0" xyz="0 0 0" />
            <geometry>
                <mesh filename="package://hera_description/meshes/manip_meshes/wrist_pan.STL" />
            </geometry>
            <material name="dark_grey">
                <color rgba="0.898039215686275 0.917647058823529 0.929411764705882 1" />
            </material>
        </visual>
        <collision>
            <origin rpy="0 0 0" xyz="0 0 0" />
            <geometry>
                <mesh filename="package://hera_description/meshes/manip_meshes/wrist_pan_col.STL" />
            </geometry>
        </collision>
        <inertial>
            <origin rpy="0 0 0" xyz="0.0113429838803915 -3.46944695195361E-18 0" />
            <mass value="0.0368976416562371" />
            <inertia ixx="1.95927087211338E-05" ixy="7.26329421268603E-21" ixz="-2.5410988417629E-21" iyy="7.36984687037621E-06" iyz="8.60646127431738E-21" izz="2.02402124370273E-05" />
        </inertial>
    </link>
    <!--joint_5: wrist_pan_joint-->
    <joint name="wrist_pan_joint" type="revolute">
        <origin rpy="0 0 0" xyz="0.1439 0 0" />
        <parent link="elbow_lift_link" />
        <child link="wrist_pan_link" />
        <axis xyz="1 0 0" />
        <limit effort="0" lower="-1.57" upper="3.14" velocity="5" />
    </joint>
    <link name="wrist_lift_link">
        <visual>
            <origin rpy="0 0 0" xyz="0 0 0" />
            <geometry>
                <mesh filename="package://hera_description/meshes/manip_meshes/wrist_lift.STL" />
            </geometry>
            <material name="dark_grey">
                <color rgba="0.898039215686275 0.917647058823529 0.929411764705882 1" />
            </material>
        </visual>
        <collision>
            <origin rpy="0 0 0" xyz="0 0 0" />
            <geometry>
                <mesh filename="package://hera_description/meshes/manip_meshes/wrist_lift_col.STL" />
            </geometry>
        </collision>
        <inertial>
            <origin rpy="0 0 0" xyz="0.0386040770329412 -0.000322583154717528 0.000293719089379529" />
            <mass value="0.482627734525522" />
            <inertia ixx="0.000146386226397184" ixy="-4.37085473836754E-07" ixz="-1.5900787088928E-13" iyy="0.000125206462596505" iyz="-1.1391259066856E-12" izz="0.000181710835049005" />
        </inertial>
    </link>
    <!--joint_6: wrist_lift_joint-->
    <joint name="wrist_lift_joint" type="revolute">
        <origin rpy="0 1.57 0" xyz="0.03885 0 0" />
        <parent link="wrist_pan_link" />
        <child link="wrist_lift_link" />
        <axis xyz="0 -1 0" />
        <limit effort="0" lower="-0.64" upper="4" velocity="5" />
    </joint>
    <link name="gripper_left_link">
        <visual>
            <origin rpy="0 0 0" xyz="0 0 0" />
            <geometry>
                <mesh filename="package://hera_description/meshes/manip_meshes/gripper_meshes/gripper_left.STL" />
            </geometry>
            <material name="dark_grey">
                <color rgba="0.898039215686275 0.917647058823529 0.929411764705882 1" />
            </material>
        </visual>
        <collision>
            <origin rpy="0 0 0" xyz="0 0 0" />
            <geometry>
                <mesh filename="package://hera_description/meshes/manip_meshes/gripper_meshes/gripper_left.STL" />
            </geometry>
        </collision>
        <inertial>
            <origin rpy="0 0 0" xyz="0.000799664295637492 -0.0665118622668557 0.00015710063142943" />
            <mass value="0.0392347308783591" />
            <inertia ixx="2.29035009049597E-05" ixy="1.82727115379582E-05" ixz="3.07510207373307E-11" iyy="5.67249052626609E-05" iyz="-1.11321771779834E-11" izz="5.94929088813273E-05" />
        </inertial>
    </link>
    <!--joint_8: gripper_left_joint-->
    <joint name="gripper_left_joint" type="revolute">
        <origin rpy="0 0 0" xyz="0.061 -0.02125 0" />
        <parent link="wrist_lift_link" />
        <child link="gripper_left_link" />
        <axis xyz="0 0 1" />
        <limit effort="0" lower="-1.5600" upper="0.6454" velocity="5" />
    </joint>
    <link name="gripper_left_end_link">
        <visual>
            <origin rpy="0 0 0" xyz="0 0 0" />
            <geometry>
                <mesh filename="package://hera_description/meshes/manip_meshes/gripper_meshes/gripper_left_end.STL" />
            </geometry>
            <material name="white">
                <color rgba="0.898039215686275 0.917647058823529 0.929411764705882 1" />
            </material>
        </visual>
        <collision>
            <origin rpy="0 0 0" xyz="0 0 0" />
            <geometry>
                <mesh filename="package://hera_description/meshes/manip_meshes/gripper_meshes/gripper_left_end.STL" />
            </geometry>
        </collision>
        <inertial>
            <origin rpy="0 0 0" xyz="0.000799664295637492 -0.0665118622668557 0.00015710063142943" />
            <mass value="0.0535202013033793" />
            <inertia ixx="2.29035009049597E-05" ixy="1.82727115379582E-05" ixz="3.07510207373307E-11" iyy="5.67249052626609E-05" iyz="-1.11321771779834E-11" izz="5.94929088813273E-05" />
        </inertial>
    </link>
    <!--joint_8_end: gripper_left_end_joint-->
    <joint name="gripper_left_end_joint" type="fixed">
        <origin rpy="0 0 0" xyz="0.0661786041848968 0.0212499999999973 0" />
        <parent link="gripper_left_link" />
        <child link="gripper_left_end_link" />
        <axis xyz="0 0 0" />
    </joint>
    <link name="gripper_right_link">
        <visual>
            <origin rpy="0 0 0" xyz="0 0 0" />
            <geometry>
                <mesh filename="package://hera_description/meshes/manip_meshes/gripper_meshes/gripper_right.STL" />
            </geometry>
            <material name="dark_grey">
                <color rgba="0.898039215686275 0.917647058823529 0.929411764705882 1" />
            </material>
        </visual>
        <collision>
            <origin rpy="0 0 0" xyz="0 0 0" />
            <geometry>
                <mesh filename="package://hera_description/meshes/manip_meshes/gripper_meshes/gripper_right_col.STL" />
            </geometry>
        </collision>
        <inertial>
            <origin rpy="0 0 0" xyz="0.0224717905842797 0.025995105661012 -1.86855826922461E-08" />
            <mass value="0.0392347304267543" />
            <inertia ixx="1.12762059938717E-05" ixy="2.39164603983455E-07" ixz="-1.49908527899727E-12" iyy="1.06667583466197E-05" iyz="1.51683951155461E-12" izz="3.59815370093277E-06" />
        </inertial>
    </link>
    <!--joint_7: gripper_right_joint-->
    <joint name="gripper_right_joint" type="revolute">
        <origin rpy="0 0 0" xyz="0.061 0.02125 0" />
        <parent link="wrist_lift_link" />
        <child link="gripper_right_link" />
        <axis xyz="0 0 1" />
        <limit effort="0" lower="-0.6454" upper="1.5600" velocity="5" />
    </joint>
    <link name="gripper_right_end_link">
        <visual>
            <origin rpy="0 0 0" xyz="0 0 0" />
            <geometry>
                <mesh filename="package://hera_description/meshes/manip_meshes/gripper_meshes/gripper_right_end.STL" />
            </geometry>
            <material name="white">
                <color rgba="0.898039215686275 0.917647058823529 0.929411764705882 1" />
            </material>
        </visual>
        <collision>
            <origin rpy="0 0 0" xyz="0 0 0" />
            <geometry>
                <mesh filename="package://hera_description/meshes/manip_meshes/gripper_meshes/gripper_right_end.STL" />
            </geometry>
        </collision>
        <inertial>
            <origin rpy="0 0 0" xyz="0.000799651866160656 0.0665118576297725 0.000157118505166365" />
            <mass value="0.0535201883186937" />
            <inertia ixx="2.29035041365173E-05" ixy="-1.8272694134383E-05" ixz="-1.47284953313777E-11" iyy="5.672487088308E-05" iyz="-6.47534317160686E-12" izz="5.94928785230653E-05" />
        </inertial>
    </link>
    <!--joint_7_end: gripper_right_end_joint-->
    <joint name="gripper_right_end_joint" type="fixed">
        <origin rpy="0 0 0" xyz="0.066179 -0.02125 0" />
        <parent link="gripper_right_link" />
        <child link="gripper_right_end_link" />
        <axis xyz="0 0 0" />
    </joint>
    <!-- ####################################################################### -->
    <!-- ####################### gazebo extensions ##############################-->
    <!-- ####################################################################### -->
    <gazebo>
        <plugin filename="libgazebo_ros_planar_move.so" name="base_controller">
            <robotNamespace>/</robotNamespace>
            <commandTopic>cmd_vel</commandTopic>
            <odometryTopic>odom</odometryTopic>
            <odometryFrame>odom</odometryFrame>
            <odometryRate>30</odometryRate>
            <cmdTimeout>-1</cmdTimeout>
            <robotBaseFrame>base_footprint</robotBaseFrame>
        </plugin>
    </gazebo>
    <gazebo reference="base_scan_front">
        <sensor name="base_scan_front" type="ray">
            <always_on>true</always_on>
            <update_rate>30</update_rate>
            <visualize>true</visualize>
            <ray>
                <scan>
                    <horizontal>
                        <samples>150</samples>
                        <resolution>1.0</resolution>
                        <min_angle>-1.45</min_angle>
                        <max_angle>1.45</max_angle>
                    </horizontal>
                </scan>
                <range>
                    <min>0.08</min>
                    <max>30.0</max>
                    <resolution>0.01</resolution>
                </range>
            </ray>
            <plugin filename="libgazebo_ros_laser.so" name="gazebo_ros_base_scan_front_controller">
                <robotNamespace>/</robotNamespace>
                <gaussianNoise>0.005</gaussianNoise>
                <alwaysOn>true</alwaysOn>
                <updateRate>30</updateRate>
                <topicName>base_scan_front</topicName>
                <frameName>base_scan_front</frameName>
            </plugin>
        </sensor>
    </gazebo>
    <gazebo reference="base_scan_back">
        <sensor name="base_scan_back" type="ray">
            <always_on>true</always_on>
            <update_rate>30</update_rate>
            <visualize>true</visualize>
            <ray>
                <scan>
                    <horizontal>
                        <samples>150</samples>
                        <resolution>1.0</resolution>
                        <min_angle>-1.45</min_angle>
                        <max_angle>1.45</max_angle>
                    </horizontal>
                </scan>
                <range>
                    <min>0.05</min>
                    <max>5.6</max>
                    <resolution>0.36</resolution>
                </range>
            </ray>
            <plugin filename="libgazebo_ros_laser.so" name="gazebo_ros_base_scan_back_controller">
                <robotNamespace>/</robotNamespace>
                <gaussianNoise>0.005</gaussianNoise>
                <alwaysOn>true</alwaysOn>
                <updateRate>30</updateRate>
                <topicName>base_scan_back</topicName>
                <frameName>base_scan_back</frameName>
            </plugin>
        </sensor>
    </gazebo>
    <gazebo reference="xtion">
        <sensor name="xtion" type="depth">
            <always_on>true</always_on>
            <visualize>true</visualize>
            <update_rate>30</update_rate>
            <camera>
                <horizontal_fov>1.0960667702524387</horizontal_fov>
                <image>
                    <format>R8G8B8</format>
                    <width>640</width>
                    <height>480</height>
                </image>
                <clip>
                    <near>0.8</near>
                    <far>3.5</far>
                </clip>
            </camera>
            <plugin filename="libgazebo_ros_openni_kinect.so" name="xtion_camera_controller">
                <robotNamespace>/</robotNamespace>
                <alwaysOn>true</alwaysOn>
                <updateRate>30</updateRate>
                <cameraName>xtion</cameraName>
                <frameName>xtion_optical</frameName>
                <depthImageTopicName>depth/image_raw</depthImageTopicName>
                <depthImageCameraInfoTopicName>depth/camera_info</depthImageCameraInfoTopicName>
                <pointCloudTopicName>depth/points</pointCloudTopicName>
                <pointCloudCutoff>0.4</pointCloudCutoff>
                <hackBaseline>0.07</hackBaseline>
                <distortionK1>0.0</distortionK1>
                <distortionK2>0.0</distortionK2>
                <distortionK3>0.0</distortionK3>
                <distortionT1>0.0</distortionT1>
                <distortionT2>0.0</distortionT2>
                <CxPrime>0.0</CxPrime>
                <Cx>0.0</Cx>
                <Cy>0.0</Cy>
                <focalLength>0.0</focalLength>
            </plugin>
        </sensor>
    </gazebo>
    <!-- kinect_one -->
    <!-- <xacro:gazebo_kinect_one
    reference="kinect_one"
    update_rate="30"/> -->
    <!-- zed2 -->
    <!-- <xacro:gazebo_zed2
    reference="zed2"
    update_rate="30"/>
  <xacro:manip_transmission/> -->
    <transmission name="trans_shoulder_pan_joint">
        <type>transmission_interface/SimpleTransmission</type>
        <joint name="shoulder_pan_joint">
            <hardwareInterface>hardware_interface/EffortJointInterface</hardwareInterface>
        </joint>
        <actuator name="shoulder_pan_joint_motor">
            <hardwareInterface>hardware_interface/EffortJointInterface</hardwareInterface>
            <mechanicalReduction>1</mechanicalReduction>
        </actuator>
    </transmission>
    <transmission name="trans_shoulder_lift_joint">
        <type>transmission_interface/SimpleTransmission</type>
        <joint name="shoulder_lift_joint">
            <hardwareInterface>hardware_interface/EffortJointInterface</hardwareInterface>
        </joint>
        <actuator name="shoulder_lift_joint_motor">
            <hardwareInterface>hardware_interface/EffortJointInterface</hardwareInterface>
            <mechanicalReduction>1</mechanicalReduction>
        </actuator>
    </transmission>
    <transmission name="trans_elbow_pan_joint">
        <type>transmission_interface/SimpleTransmission</type>
        <joint name="elbow_pan_joint">
            <hardwareInterface>hardware_interface/EffortJointInterface</hardwareInterface>
        </joint>
        <actuator name="elbow_pan_joint_motor">
            <hardwareInterface>hardware_interface/EffortJointInterface</hardwareInterface>
            <mechanicalReduction>1</mechanicalReduction>
        </actuator>
    </transmission>
    <transmission name="trans_elbow_lift_joint">
        <type>transmission_interface/SimpleTransmission</type>
        <joint name="elbow_lift_joint">
            <hardwareInterface>hardware_interface/EffortJointInterface</hardwareInterface>
        </joint>
        <actuator name="elbow_lift_joint_motor">
            <hardwareInterface>hardware_interface/EffortJointInterface</hardwareInterface>
            <mechanicalReduction>1</mechanicalReduction>
        </actuator>
    </transmission>
    <transmission name="trans_wrist_pan_joint">
        <type>transmission_interface/SimpleTransmission</type>
        <joint name="wrist_pan_joint">
            <hardwareInterface>hardware_interface/EffortJointInterface</hardwareInterface>
        </joint>
        <actuator name="wrist_pan_joint_motor">
            <hardwareInterface>hardware_interface/EffortJointInterface</hardwareInterface>
            <mechanicalReduction>1</mechanicalReduction>
        </actuator>
    </transmission>
    <transmission name="trans_wrist_lift_joint">
        <type>transmission_interface/SimpleTransmission</type>
        <joint name="wrist_lift_joint">
            <hardwareInterface>hardware_interface/EffortJointInterface</hardwareInterface>
        </joint>
        <actuator name="wrist_lift_joint_motor">
            <hardwareInterface>hardware_interface/EffortJointInterface</hardwareInterface>
            <mechanicalReduction>1</mechanicalReduction>
        </actuator>
    </transmission>
    <transmission name="trans_gripper_left_joint">
        <type>transmission_interface/SimpleTransmission</type>
        <joint name="gripper_left_joint">
            <hardwareInterface>hardware_interface/EffortJointInterface</hardwareInterface>
        </joint>
        <actuator name="gripper_left_joint_motor">
            <hardwareInterface>hardware_interface/EffortJointInterface</hardwareInterface>
            <mechanicalReduction>1</mechanicalReduction>
        </actuator>
    </transmission>
    <transmission name="trans_gripper_right_joint">
        <type>transmission_interface/SimpleTransmission</type>
        <joint name="gripper_right_joint">
            <hardwareInterface>hardware_interface/EffortJointInterface</hardwareInterface>
        </joint>
        <actuator name="gripper_right_joint_motor">
            <hardwareInterface>hardware_interface/EffortJointInterface</hardwareInterface>
            <mechanicalReduction>1</mechanicalReduction>
        </actuator>
    </transmission>
</robot>

